[2025-05-21T09:22:29.693+0000] {taskinstance.py:1159} INFO - Dependencies all met for dep_context=non-requeueable deps ti=<TaskInstance: kafka_to_snowflake.consume_and_store manual__2025-05-21T09:09:53+00:00 [queued]>
[2025-05-21T09:22:29.699+0000] {taskinstance.py:1159} INFO - Dependencies all met for dep_context=requeueable deps ti=<TaskInstance: kafka_to_snowflake.consume_and_store manual__2025-05-21T09:09:53+00:00 [queued]>
[2025-05-21T09:22:29.701+0000] {taskinstance.py:1361} INFO - Starting attempt 2 of 2
[2025-05-21T09:22:29.708+0000] {taskinstance.py:1382} INFO - Executing <Task(PythonOperator): consume_and_store> on 2025-05-21 09:09:53+00:00
[2025-05-21T09:22:29.715+0000] {standard_task_runner.py:57} INFO - Started process 375 to run task
[2025-05-21T09:22:29.720+0000] {standard_task_runner.py:84} INFO - Running: ['***', 'tasks', 'run', 'kafka_to_snowflake', 'consume_and_store', 'manual__2025-05-21T09:09:53+00:00', '--job-id', '34', '--raw', '--subdir', 'DAGS_FOLDER/kafka_to_snowflake.py', '--cfg-path', '/tmp/tmpzmk0cdxu']
[2025-05-21T09:22:29.725+0000] {standard_task_runner.py:85} INFO - Job 34: Subtask consume_and_store
[2025-05-21T09:22:29.749+0000] {logging_mixin.py:154} WARNING - /home/***/.local/lib/python3.8/site-packages/***/settings.py:195 DeprecationWarning: The sql_alchemy_conn option in [core] has been moved to the sql_alchemy_conn option in [database] - the old setting has been used, but please update your config.
[2025-05-21T09:22:29.784+0000] {task_command.py:416} INFO - Running <TaskInstance: kafka_to_snowflake.consume_and_store manual__2025-05-21T09:09:53+00:00 [running]> on host 181c87754ed7
[2025-05-21T09:22:29.873+0000] {taskinstance.py:1662} INFO - Exporting env vars: AIRFLOW_CTX_DAG_OWNER='***' AIRFLOW_CTX_DAG_ID='kafka_to_snowflake' AIRFLOW_CTX_TASK_ID='consume_and_store' AIRFLOW_CTX_EXECUTION_DATE='2025-05-21T09:09:53+00:00' AIRFLOW_CTX_TRY_NUMBER='2' AIRFLOW_CTX_DAG_RUN_ID='manual__2025-05-21T09:09:53+00:00'
[2025-05-21T09:22:29.875+0000] {kafka_to_snowflake.py:58} INFO - Starting Kafka â†’ Snowflake ingestion
[2025-05-21T09:22:29.881+0000] {conn.py:396} INFO - <BrokerConnection client_id=kafka-python-2.2.7, node_id=bootstrap-0 host=kafka:29092 <connecting> [IPv4 ('172.18.0.3', 29092)]>: connecting to kafka:29092 [('172.18.0.3', 29092) IPv4]
[2025-05-21T09:22:29.916+0000] {conn.py:618} INFO - <BrokerConnection client_id=kafka-python-2.2.7, node_id=bootstrap-0 host=kafka:29092 <checking_api_versions_recv> [IPv4 ('172.18.0.3', 29092)]>: Broker version identified as 2.6
[2025-05-21T09:22:29.917+0000] {conn.py:457} INFO - <BrokerConnection client_id=kafka-python-2.2.7, node_id=bootstrap-0 host=kafka:29092 <connected> [IPv4 ('172.18.0.3', 29092)]>: Connection complete.
[2025-05-21T09:22:29.918+0000] {consumer.py:120} WARNING - group_id is None: disabling auto-commit.
[2025-05-21T09:22:29.919+0000] {subscription_state.py:177} INFO - Updating subscribed topics to: ('flights',)
[2025-05-21T09:22:29.924+0000] {subscription_state.py:246} INFO - Updated partition assignment: [('flights', 0)]
[2025-05-21T09:22:29.925+0000] {conn.py:396} INFO - <BrokerConnection client_id=kafka-python-2.2.7, node_id=1001 host=kafka:29092 <connecting> [IPv4 ('172.18.0.3', 29092)]>: connecting to kafka:29092 [('172.18.0.3', 29092) IPv4]
[2025-05-21T09:22:29.926+0000] {conn.py:457} INFO - <BrokerConnection client_id=kafka-python-2.2.7, node_id=1001 host=kafka:29092 <connected> [IPv4 ('172.18.0.3', 29092)]>: Connection complete.
[2025-05-21T09:22:29.926+0000] {conn.py:945} INFO - <BrokerConnection client_id=kafka-python-2.2.7, node_id=bootstrap-0 host=kafka:29092 <connected> [IPv4 ('172.18.0.3', 29092)]>: Closing connection. 
[2025-05-21T09:22:29.942+0000] {fetcher.py:413} INFO - Resetting offset for partition ('flights', 0) to offset 0.
[2025-05-21T09:22:44.368+0000] {local_task_job_runner.py:115} ERROR - Received SIGTERM. Terminating subprocesses
[2025-05-21T09:22:44.437+0000] {process_utils.py:131} INFO - Sending 15 to group 375. PIDs of all processes in the group: [375]
[2025-05-21T09:22:44.452+0000] {process_utils.py:86} INFO - Sending the signal 15 to group 375
[2025-05-21T09:22:44.463+0000] {taskinstance.py:1632} ERROR - Received SIGTERM. Terminating subprocesses.
[2025-05-21T09:22:44.508+0000] {taskinstance.py:1937} ERROR - Task failed with exception
Traceback (most recent call last):
  File "/home/airflow/.local/lib/python3.8/site-packages/airflow/operators/python.py", line 192, in execute
    return_value = self.execute_callable()
  File "/home/airflow/.local/lib/python3.8/site-packages/airflow/operators/python.py", line 209, in execute_callable
    return self.python_callable(*self.op_args, **self.op_kwargs)
  File "/opt/airflow/dags/kafka_to_snowflake.py", line 73, in consume_and_store
    for msg in consumer:
  File "/home/airflow/.local/lib/python3.8/site-packages/kafka/consumer/group.py", line 1188, in __next__
    return next(self._iterator)
  File "/home/airflow/.local/lib/python3.8/site-packages/kafka/consumer/group.py", line 1160, in _message_generator_v2
    record_map = self.poll(timeout_ms=timeout_ms, update_offsets=False)
  File "/home/airflow/.local/lib/python3.8/site-packages/kafka/consumer/group.py", line 684, in poll
    records = self._poll_once(timer, max_records, update_offsets=update_offsets)
  File "/home/airflow/.local/lib/python3.8/site-packages/kafka/consumer/group.py", line 729, in _poll_once
    self._client.poll(timeout_ms=poll_timeout_ms)
  File "/home/airflow/.local/lib/python3.8/site-packages/kafka/client_async.py", line 685, in poll
    self._poll(timeout / 1000)
  File "/home/airflow/.local/lib/python3.8/site-packages/kafka/client_async.py", line 728, in _poll
    ready = self._selector.select(timeout)
  File "/usr/local/lib/python3.8/selectors.py", line 468, in select
    fd_event_list = self._selector.poll(timeout, max_ev)
  File "/home/airflow/.local/lib/python3.8/site-packages/airflow/models/taskinstance.py", line 1634, in signal_handler
    raise AirflowException("Task received SIGTERM signal")
airflow.exceptions.AirflowException: Task received SIGTERM signal
[2025-05-21T09:22:44.521+0000] {taskinstance.py:1400} INFO - Marking task as FAILED. dag_id=kafka_to_snowflake, task_id=consume_and_store, execution_date=20250521T090953, start_date=20250521T092229, end_date=20250521T092244
[2025-05-21T09:22:44.544+0000] {standard_task_runner.py:104} ERROR - Failed to execute job 34 for task consume_and_store (Task received SIGTERM signal; 375)
[2025-05-21T09:22:44.557+0000] {process_utils.py:79} INFO - Process psutil.Process(pid=375, status='terminated', exitcode=1, started='09:22:29') (375) terminated with exit code 1
[2025-05-21T09:22:44.560+0000] {local_task_job_runner.py:228} INFO - Task exited with return code 143
[2025-05-21T09:22:44.597+0000] {taskinstance.py:2778} INFO - 0 downstream tasks scheduled from follow-on schedule check
